Workbook

Sheet Dashboard
C2: سجل متابعة مشروع الحوكمة
C3: اللجنة التوجيهية — شركة العطيشان القابضة
B5: تاريخ آخر تحديث | E5: تاريخ استخراج التقرير | H5: الجهة المسؤولة عن التحديث | K5: نسخة التقرير
B6: =TEXT(MAX(tblDeliverables[تاريخ آخر تحديث]),"yyyy-mm-dd") -> 2026-06-10 | E6: =TEXT(TODAY(),"yyyy-mm-dd") -> 2026-06-18 | H6: فريق الحوكمة | K6: V1.0
B8: المؤشرات الرئيسية
B9: =COUNTA(tblDeliverables[المخرج]) -> 22 | E9: =COUNTIF(tblDeliverables[الحالة الحالية],"مستلم") -> 6 | H9: =COUNTIF(tblDeliverables[الحالة الحالية],"مراجعة المختصين") -> 8 | K9: =COUNTIF(tblDeliverables[الحالة الحالية],"التعديل لدى الحلول القانونية") -> 3
B10: إجمالي المخرجات | E10: المستلمة | H10: تحت المراجعة | K10: لدى الحلول القانونية
B12: =COUNTIF(tblDeliverables[الحالة الحالية],"مراجعة لجنة الحوكمة") -> 2 | E12: =COUNTIF(tblDeliverables[الحالة الحالية],"مراجعة لجنة الترشيحات والمكافآت") -> 1 | H12: =COUNTIF(tblDeliverables[الحالة الحالية],"اعتماد مجلس الإدارة") -> 1 | K12: =COUNTIF(tblDeliverables[الحالة الحالية],"معتمد ونافذ") -> 1
B13: لدى لجنة الحوكمة | E13: لدى لجنة الترشيحات | H13: جاهزة للاعتماد | K13: المعتمدة
B15: =COUNTIF(tblDeliverables[مؤشر الالتزام الزمني],"متأخر") -> 1 | E15: =COUNTIFS(tblDeliverables[الأولوية],"عالية",tblDeliverables[الحالة الحالية],"<>معتمد ونافذ") -> 9 | H15: =IFERROR(ROUND(AVERAGE(tblDeliverables[أيام المراجعة]),1),0) -> 88.6 | K15: =IFERROR(COUNTIF(tblDeliverables[الحالة الحالية],"معتمد ونافذ")/COUNTA(tblDeliverables[المخرج]),0) -> 0.045454545
B16: المتأخرة | E16: الحرجة | H16: متوسط أيام المراجعة | K16: نسبة الإنجاز الكلية
B18: ملخص اللجنة التوجيهية
B19: المخرجات المتأخرة | E19: =IF(Data!$V$210="","لا يوجد",Data!$V$210) -> مصفوفة الصلاحيات الشاملة
B20: المخرجات الحرجة | E20: =IF(Data!$W$210="","لا يوجد",Data!$W$210) -> لائحة مجلس الإدارة، لائحة لجنة المراجعة، لائحة لجنة الترشيحات والمكافآت، مصفوفة الصلاحيات الشاملة، سياسة تعارض المصالح، سياسة إدارة المخاطر، سياسة الاستثمار والشركات التابعة، تطوير الاستراتيجية الشاملة للمجموعة، مؤشرات الأداء الاستراتيجية
B21: القرارات المفتوحة | E21: =IF(Data!$X$210="","لا يوجد",Data!$X$210) -> مراجعة حالة المخرجات المتأخرة، الموافقة على رفع لوائح اللجان للمجلس
B22: الإجراءات المستحقة خلال أسبوعين | E22: =IF(Data!$Y$210="","لا يوجد",Data!$Y$210) -> تسريع اعتماد مصفوفة الصلاحيات الشاملة، جدولة جلسة اعتماد لائحة مجلس الإدارة
B24: لوحة التحكم التفاعلية — اختر البيانات التي تريد عرضها في الرسم الرئيسي
B25: اعرض التوزيع حسب: | E25: الحالة | G25: تصفية بالتصنيف: | I25: الكل | K25: تصفية بالأولوية: | M25: الكل
B26: عند تغيير أي خيار أعلاه يُعاد تشكيل (الرسم الرئيسي التفاعلي) تلقائياً.
B27: الرسوم البيانية
B28: ="◆ الرسم الرئيسي التفاعلي: "&Data!$AA$1 -> ◆ الرسم الرئيسي التفاعلي: التوزيع حسب الحالة
B125: المرجع الرسمي للجنة التوجيهية حتى الإقفال النهائي لمشروع الحوكمة المستهدف بتاريخ 2026-08-15
B126: إشراف رئيس اللجنة التوجيهية: محمد البوعلي
B127: إعداد: شركة أمين للذكاء الاصطناعي — مقدَّم إلى: شركة العطيشان القابضة

Sheet Lookup Lists
A1: القوائم المرجعية
A2: تُستخدم هذه القوائم تلقائياً في جميع القوائم المنسدلة داخل الملف — يمكن التعديل عليها بالإضافة أو الحذف. | G2: قوائم التحكم بالرسم البياني التفاعلي في لوحة المؤشرات.
A4: الحالات | B4: الأولويات | C4: الجهات | D4: التصنيفات | E4: حالات القرارات | G4: محاور الرسم | H4: تصفية التصنيف | I4: تصفية الأولوية | J4: الالتزام (مرجع) | K4: النطاق
A5: مستلم | B5: عالية | C5: الملاك | D5: حوكمة | E5: مفتوح | G5: الحالة | H5: الكل | I5: الكل | J5: متأخر | K5: ضمن النطاق
A6: مراجعة المختصين | B6: متوسطة | C6: مجلس الإدارة | D6: القابضة | E6: مغلق | G6: الأولوية | H6: حوكمة | I6: عالية | J6: ضمن الخطة | K6: خارج النطاق
A7: التعديل لدى الحلول القانونية | B7: منخفضة | C7: لجنة المراجعة | D7: تشغيلي | E7: متأخر | G7: التصنيف | H7: القابضة | I7: متوسطة | J7: مكتمل
A8: مراجعة لجنة الحوكمة | C8: لجنة الترشيحات والمكافآت | D8: تنظيمي | G8: النطاق | H8: تشغيلي | I8: منخفضة
A9: مراجعة لجنة الترشيحات والمكافآت | C9: الرئيس التنفيذي | G9: الالتزام الزمني | H9: تنظيمي
A10: اعتماد مجلس الإدارة | C10: الإدارة التنفيذية
A11: معتمد ونافذ | C11: عامر البيروتي
C12: أمين المجلس
C13: الموارد البشرية
C14: الإدارة المالية
C15: تقنية المعلومات
C16: الشؤون القانونية
C17: الإدارة التجارية
C18: العمليات والتشغيل
C19: المشتريات والمستودعات
C20: الحلول القانونية
C21: فريق الحوكمة

Sheet Deliverables Register
A1: سجل متابعة مخرجات مشروع الحوكمة — شركة العطيشان القابضة
A2: رقم | B2: المخرج | C2: التصنيف | D2: المختص / الجهة المراجعة | E2: تاريخ استلام المخرج | F2: عدد المراجعات | G2: تاريخ الإرسال للمختص | H2: أيام المراجعة | I2: الحالة الحالية | J2: المسؤول الحالي | K2: الأولوية | L2: تاريخ الإغلاق المستهدف | M2: تاريخ آخر تحديث | N2: آخر جهة قامت بالتحديث | O2: الملاحظات | P2: النطاق | Q2: مؤشر الالتزام الزمني
A3: 1 | B3: لائحة الجمعية العمومية | C3: حوكمة | D3: مجلس الإدارة | E3: 46034 | F3: 3 | G3: 46042 | H3: =IF(G3="","",IF(I3="معتمد ونافذ","",TODAY()-G3)) | I3: معتمد ونافذ | J3: أمين المجلس | K3: عالية | L3: 46096 | M3: 46097 | N3: مجلس الإدارة | P3: ضمن النطاق | Q3: =IF(I3="معتمد ونافذ","مكتمل",IF(L3="","غير محدد",IF(TODAY()>L3,"متأخر","ضمن الخطة"))) -> مكتمل
A4: 2 | B4: لائحة مجلس الإدارة | C4: حوكمة | D4: مجلس الإدارة | E4: 46034 | F4: 2 | G4: 46047 | H4: =IF(G4="","",IF(I4="معتمد ونافذ","",TODAY()-G4)) -> 144 | I4: اعتماد مجلس الإدارة | J4: أمين المجلس | K4: عالية | L4: 46203 | M4: 46181 | N4: فريق الحوكمة | O4: بانتظار جلسة المجلس القادمة | P4: ضمن النطاق | Q4: =IF(I4="معتمد ونافذ","مكتمل",IF(L4="","غير محدد",IF(TODAY()>L4,"متأخر","ضمن الخطة"))) -> ضمن الخطة
A5: 3 | B5: لائحة لجنة المراجعة | C5: حوكمة | D5: لجنة المراجعة | E5: 46056 | F5: 2 | G5: 46068 | H5: =IF(G5="","",IF(I5="معتمد ونافذ","",TODAY()-G5)) -> 123 | I5: مراجعة لجنة الحوكمة | J5: فريق الحوكمة | K5: عالية | L5: 46198 | M5: 46178 | N5: لجنة المراجعة | P5: ضمن النطاق | Q5: =IF(I5="معتمد ونافذ","مكتمل",IF(L5="","غير محدد",IF(TODAY()>L5,"متأخر","ضمن الخطة"))) -> ضمن الخطة
A6: 4 | B6: لائحة لجنة الترشيحات والمكافآت | C6: حوكمة | D6: لجنة الترشيحات والمكافآت | E6: 46056 | F6: 1 | G6: 46071 | H6: =IF(G6="","",IF(I6="معتمد ونافذ","",TODAY()-G6)) -> 120 | I6: مراجعة لجنة الترشيحات والمكافآت | J6: لجنة الترشيحات والمكافآت | K6: عالية | L6: 46193 | M6: 46175 | N6: فريق الحوكمة | O6: تمت موافاتهم بالنسخة المحدثة | P6: ضمن النطاق | Q6: =IF(I6="معتمد ونافذ","مكتمل",IF(L6="","غير محدد",IF(TODAY()>L6,"متأخر","ضمن الخطة"))) -> ضمن الخطة
A7: 5 | B7: لائحة لجنة الاستثمار | C7: حوكمة | D7: الإدارة المالية | E7: 46082 | F7: 1 | G7: 46091 | H7: =IF(G7="","",IF(I7="معتمد ونافذ","",TODAY()-G7)) -> 100 | I7: مراجعة المختصين | J7: الإدارة المالية | K7: متوسطة | L7: 46218 | M7: 46170 | N7: الإدارة المالية | P7: ضمن النطاق | Q7: =IF(I7="معتمد ونافذ","مكتمل",IF(L7="","غير محدد",IF(TODAY()>L7,"متأخر","ضمن الخطة"))) -> ضمن الخطة
A8: 6 | B8: لائحة اللجنة التنفيذية | C8: حوكمة | D8: الرئيس التنفيذي | E8: 46086 | F8: 1 | G8: 46093 | H8: =IF(G8="","",IF(I8="معتمد ونافذ","",TODAY()-G8)) -> 98 | I8: التعديل لدى الحلول القانونية | J8: الحلول القانونية | K8: متوسطة | L8: 46204 | M8: 46183 | N8: الحلول القانونية | P8: ضمن النطاق | Q8: =IF(I8="معتمد ونافذ","مكتمل",IF(L8="","غير محدد",IF(TODAY()>L8,"متأخر","ضمن الخطة"))) -> ضمن الخطة
A9: 7 | B9: لائحة الرئيس التنفيذي | C9: حوكمة | D9: الرئيس التنفيذي | E9: 46162 | F9: 0 | H9: =IF(G9="","",IF(I9="معتمد ونافذ","",TODAY()-G9)) | I9: مستلم | J9: فريق الحوكمة | K9: متوسطة | L9: 46223 | M9: 46162 | N9: فريق الحوكمة | O9: بانتظار بدء المراجعة | P9: ضمن النطاق | Q9: =IF(I9="معتمد ونافذ","مكتمل",IF(L9="","غير محدد",IF(TODAY()>L9,"متأخر","ضمن الخطة"))) -> ضمن الخطة
A10: 8 | B10: استمارة قياس القدرة المؤسسية | C10: تنظيمي | D10: فريق الحوكمة | E10: 46167 | F10: 0 | H10: =IF(G10="","",IF(I10="معتمد ونافذ","",TODAY()-G10)) | I10: مستلم | J10: فريق الحوكمة | K10: منخفضة | L10: 46233 | M10: 46167 | N10: فريق الحوكمة | P10: ضمن النطاق | Q10: =IF(I10="معتمد ونافذ","مكتمل",IF(L10="","غير محدد",IF(TODAY()>L10,"متأخر","ضمن الخطة"))) -> ضمن الخطة
A11: 9 | B11: مصفوفة الصلاحيات الشاملة | C11: حوكمة | D11: الإدارة التنفيذية | E11: 46073 | F11: 2 | G11: 46083 | H11: =IF(G11="","",IF(I11="معتمد ونافذ","",TODAY()-G11)) -> 108 | I11: مراجعة المختصين | J11: الإدارة التنفيذية | K11: عالية | L11: 46157 | M11: 46174 | N11: الإدارة التنفيذية | O11: تجاوزت الموعد المستهدف | P11: ضمن النطاق | Q11: =IF(I11="معتمد ونافذ","مكتمل",IF(L11="","غير محدد",IF(TODAY()>L11,"متأخر","ضمن الخطة"))) -> متأخر
A12: 10 | B12: سياسة الإفصاح والشفافية | C12: تنظيمي | D12: الشؤون القانونية | E12: 46091 | F12: 1 | G12: 46099 | H12: =IF(G12="","",IF(I12="معتمد ونافذ","",TODAY()-G12)) -> 92 | I12: التعديل لدى الحلول القانونية | J12: الحلول القانونية | K12: متوسطة | L12: 46208 | M12: 46182 | N12: الحلول القانونية | P12: ضمن النطاق | Q12: =IF(I12="معتمد ونافذ","مكتمل",IF(L12="","غير محدد",IF(TODAY()>L12,"متأخر","ضمن الخطة"))) -> ضمن الخطة
A13: 11 | B13: سياسة تعارض المصالح | C13: تنظيمي | D13: الشؤون القانونية | E13: 46092 | F13: 2 | G13: 46101 | H13: =IF(G13="","",IF(I13="معتمد ونافذ","",TODAY()-G13)) -> 90 | I13: مراجعة لجنة الحوكمة | J13: فريق الحوكمة | K13: عالية | L13: 46201 | M13: 46177 | N13: فريق الحوكمة | P13: ضمن النطاق | Q13: =IF(I13="معتمد ونافذ","مكتمل",IF(L13="","غير محدد",IF(TODAY()>L13,"متأخر","ضمن الخطة"))) -> ضمن الخطة
A14: 12 | B14: سياسة إدارة المخاطر | C14: تنظيمي | D14: الإدارة التنفيذية | E14: 46113 | F14: 1 | G14: 46120 | H14: =IF(G14="","",IF(I14="معتمد ونافذ","",TODAY()-G14)) -> 71 | I14: مراجعة المختصين | J14: الإدارة التنفيذية | K14: عالية | L14: 46213 | M14: 46172 | N14: الإدارة التنفيذية | P14: ضمن النطاق | Q14: =IF(I14="معتمد ونافذ","مكتمل",IF(L14="","غير محدد",IF(TODAY()>L14,"متأخر","ضمن الخطة"))) -> ضمن الخطة
A15: 13 | B15: سياسة مكافحة الغش والاحتيال | C15: تنظيمي | D15: الشؤون القانونية | E15: 46160 | F15: 0 | H15: =IF(G15="","",IF(I15="معتمد ونافذ","",TODAY()-G15)) | I15: مستلم | J15: فريق الحوكمة | K15: متوسطة | L15: 46228 | M15: 46160 | N15: فريق الحوكمة | P15: ضمن النطاق | Q15: =IF(I15="معتمد ونافذ","مكتمل",IF(L15="","غير محدد",IF(TODAY()>L15,"متأخر","ضمن الخطة"))) -> ضمن الخطة
A16: 14 | B16: سياسة الالتزام والامتثال | C16: تنظيمي | D16: الشؤون القانونية | E16: 46127 | F16: 1 | G16: 46134 | H16: =IF(G16="","",IF(I16="معتمد ونافذ","",TODAY()-G16)) -> 57 | I16: مراجعة المختصين | J16: الشؤون القانونية | K16: متوسطة | L16: 46215 | M16: 46171 | N16: الشؤون القانونية | P16: ضمن النطاق | Q16: =IF(I16="معتمد ونافذ","مكتمل",IF(L16="","غير محدد",IF(TODAY()>L16,"متأخر","ضمن الخطة"))) -> ضمن الخطة
A17: 15 | B17: سياسة الاستثمار والشركات التابعة | C17: القابضة | D17: الإدارة المالية | E17: 46114 | F17: 1 | G17: 46124 | H17: =IF(G17="","",IF(I17="معتمد ونافذ","",TODAY()-G17)) -> 67 | I17: مراجعة المختصين | J17: الإدارة المالية | K17: عالية | L17: 46211 | M17: 46176 | N17: الإدارة المالية | P17: ضمن النطاق | Q17: =IF(I17="معتمد ونافذ","مكتمل",IF(L17="","غير محدد",IF(TODAY()>L17,"متأخر","ضمن الخطة"))) -> ضمن الخطة
A18: 16 | B18: متابعة الأداء التشغيلي للشركات التابعة | C18: تشغيلي | D18: العمليات والتشغيل | E18: 46164 | F18: 0 | H18: =IF(G18="","",IF(I18="معتمد ونافذ","",TODAY()-G18)) | I18: مستلم | J18: العمليات والتشغيل | K18: متوسطة | L18: 46235 | M18: 46164 | N18: العمليات والتشغيل | P18: ضمن النطاق | Q18: =IF(I18="معتمد ونافذ","مكتمل",IF(L18="","غير محدد",IF(TODAY()>L18,"متأخر","ضمن الخطة"))) -> ضمن الخطة
A19: 17 | B19: تطوير الاستراتيجية الشاملة للمجموعة | C19: القابضة | D19: الرئيس التنفيذي | E19: 46096 | F19: 2 | G19: 46106 | H19: =IF(G19="","",IF(I19="معتمد ونافذ","",TODAY()-G19)) -> 85 | I19: مراجعة المختصين | J19: الرئيس التنفيذي | K19: عالية | L19: 46244 | M19: 46180 | N19: الرئيس التنفيذي | O19: مخرج محوري | P19: ضمن النطاق | Q19: =IF(I19="معتمد ونافذ","مكتمل",IF(L19="","غير محدد",IF(TODAY()>L19,"متأخر","ضمن الخطة"))) -> ضمن الخطة
A20: 18 | B20: سياسة الإبلاغ عن المخالفات | C20: تنظيمي | D20: الشؤون القانونية | E20: 46117 | F20: 1 | G20: 46127 | H20: =IF(G20="","",IF(I20="معتمد ونافذ","",TODAY()-G20)) -> 64 | I20: التعديل لدى الحلول القانونية | J20: الحلول القانونية | K20: متوسطة | L20: 46221 | M20: 46179 | N20: الحلول القانونية | P20: ضمن النطاق | Q20: =IF(I20="معتمد ونافذ","مكتمل",IF(L20="","غير محدد",IF(TODAY()>L20,"متأخر","ضمن الخطة"))) -> ضمن الخطة
A21: 19 | B21: سياسة البيانات والخصوصية | C21: تنظيمي | D21: تقنية المعلومات | E21: 46132 | F21: 1 | G21: 46140 | H21: =IF(G21="","",IF(I21="معتمد ونافذ","",TODAY()-G21)) -> 51 | I21: مراجعة المختصين | J21: تقنية المعلومات | K21: متوسطة | L21: 46225 | M21: 46169 | N21: تقنية المعلومات | P21: ضمن النطاق | Q21: =IF(I21="معتمد ونافذ","مكتمل",IF(L21="","غير محدد",IF(TODAY()>L21,"متأخر","ضمن الخطة"))) -> ضمن الخطة
A22: 20 | B22: مصفوفة الصلاحيات الاستثمارية | C22: القابضة | D22: الإدارة المالية | E22: 46168 | F22: 0 | H22: =IF(G22="","",IF(I22="معتمد ونافذ","",TODAY()-G22)) | I22: مستلم | J22: الإدارة المالية | K22: متوسطة | L22: 46239 | M22: 46168 | N22: الإدارة المالية | P22: ضمن النطاق | Q22: =IF(I22="معتمد ونافذ","مكتمل",IF(L22="","غير محدد",IF(TODAY()>L22,"متأخر","ضمن الخطة"))) -> ضمن الخطة
A23: 21 | B23: مصفوفة صلاحيات الشركات التابعة | C23: القابضة | D23: الإدارة التنفيذية | E23: 46169 | F23: 0 | H23: =IF(G23="","",IF(I23="معتمد ونافذ","",TODAY()-G23)) | I23: مستلم | J23: الإدارة التنفيذية | K23: منخفضة | L23: 46242 | M23: 46169 | N23: الإدارة التنفيذية | P23: ضمن النطاق | Q23: =IF(I23="معتمد ونافذ","مكتمل",IF(L23="","غير محدد",IF(TODAY()>L23,"متأخر","ضمن الخطة"))) -> ضمن الخطة
A24: 22 | B24: مؤشرات الأداء الاستراتيجية | C24: القابضة | D24: الرئيس التنفيذي | E24: 46122 | F24: 1 | G24: 46132 | H24: =IF(G24="","",IF(I24="معتمد ونافذ","",TODAY()-G24)) -> 59 | I24: مراجعة المختصين | J24: الرئيس التنفيذي | K24: عالية | L24: 46246 | M24: 46174 | N24: الرئيس التنفيذي | P24: ضمن النطاق | Q24: =IF(I24="معتمد ونافذ","مكتمل",IF(L24="","غير محدد",IF(TODAY()>L24,"متأخر","ضمن الخطة"))) -> ضمن الخطة

Sheet Steering Committee Meetings
A1: محاضر وقرارات اللجنة التوجيهية — شركة العطيشان القابضة
A2: رقم الاجتماع | B2: تاريخ الاجتماع | C2: عدد الحضور | D2: عدد الغياب | E2: أهم القرارات | F2: الإجراءات المطلوبة | G2: المسؤول | H2: تاريخ الاستحقاق | I2: الحالة
A3: 1 | B3: 46063 | C3: 7 | D3: 1 | E3: اعتماد خطة مشروع الحوكمة والجدول الزمني | F3: رفع مسودة اللوائح الأساسية | G3: فريق الحوكمة | H3: 46082 | I3: مغلق
A4: 2 | B4: 46099 | C4: 6 | D4: 2 | E4: إقرار منهجية المراجعة عبر الحلول القانونية | F4: تسليم سياسات الالتزام والمخاطر | G4: الشؤون القانونية | H4: 46143 | I4: مغلق
A5: 3 | B5: 46154 | C5: 7 | D5: 1 | E5: مراجعة حالة المخرجات المتأخرة | F5: تسريع اعتماد مصفوفة الصلاحيات الشاملة | G5: الإدارة التنفيذية | H5: 46198 | I5: مفتوح
A6: 4 | B6: 46182 | C6: 6 | D6: 2 | E6: الموافقة على رفع لوائح اللجان للمجلس | F6: جدولة جلسة اعتماد لائحة مجلس الإدارة | G6: أمين المجلس | H6: 46203 | I6: مفتوح

Sheet Data
A1: الحالة | B1: العدد | D1: الجهة | E1: العدد | G1: الأولوية | H1: العدد | J1: الالتزام الزمني | K1: العدد | M1: الإنجاز | N1: العدد | Q1: المتأخرة | R1: الحرجة | S1: قرارات مفتوحة | T1: إجراءات مستحقة | AA1: ="التوزيع حسب "&Dashboard!$E$25&IF(Dashboard!$I$25="الكل",""," | التصنيف: "&Dashboard!$I$25)&IF(Dashboard!$M$25="الكل",""," | الأولوية: "&Dashboard!$M$25) -> التوزيع حسب الحالة | AB1: الفئة | AC1: العدد
A2: مستلم | B2: =COUNTIF(tblDeliverables[الحالة الحالية],"مستلم") -> 6 | D2: الملاك | E2: =COUNTIF(tblDeliverables[المختص / الجهة المراجعة],"الملاك") -> 0 | G2: عالية | H2: =COUNTIF(tblDeliverables[الأولوية],"عالية") -> 10 | J2: متأخر | K2: =COUNTIF(tblDeliverables[مؤشر الالتزام الزمني],"متأخر") -> 1 | M2: معتمد ونافذ | N2: =COUNTIF(tblDeliverables[الحالة الحالية],"معتمد ونافذ") -> 1 | AB2: =IFERROR(IF(Dashboard!$E$25="الحالة",INDEX('Lookup Lists'!$A$5:$A$11,1),IF(Dashboard!$E$25="الأولوية",IF(1<=3,INDEX('Lookup Lists'!$B$5:$B$7,1),""),IF(Dashboard!$E$25="التصنيف",IF(1<=4,INDEX('Lookup Lists'!$D$5:$D$8,1),""),IF(Dashboard!$E$25="النطاق",IF(1<=2,INDEX('Lookup Lists'!$K$5:$K$6,1),""),IF(Dashboard!$E$25="الالتزام الزمني",IF(1<=3,INDEX('Lookup Lists'!$J$5:$J$7,1),""),""))))),"") -> مستلم | AC2: =IF($AB$2="",NA(),IF(Dashboard!$E$25="الحالة",SUMPRODUCT((tblDeliverables[الحالة الحالية]=$AB$2)*((( Dashboard!$I$25="الكل")+(tblDeliverables[التصنيف]=Dashboard!$I$25))>0)*((( Dashboard!$M$25="الكل")+(tblDeliverables[الأولوية]=Dashboard!$M$25))>0)),IF(Dashboard!$E$25="الأولوية",SUMPRODUCT((tblDeliverables[الأولوية]=$AB$2)*((( Dashboard!$I$25="الكل")+(tblDeliverables[التصنيف]=Dashboard!$I$25))>0)),IF(Dashboard!$E$25="التصنيف",SUMPRODUCT((tblDeliverables[التصنيف]=$AB$2)*((( Dashboard!$M$25="الكل")+(tblDeliverables[الأولوية]=Dashboard!$M$25))>0)),IF(Dashboard!$E$25="النطاق",SUMPRODUCT((tblDeliverables[النطاق]=$AB$2)*((( Dashboard!$I$25="الكل")+(tblDeliverables[التصنيف]=Dashboard!$I$25))>0)*((( Dashboard!$M$25="الكل")+(tblDeliverables[الأولوية]=Dashboard!$M$25))>0)),IF(Dashboard!$E$25="الالتزام الزمني",SUMPRODUCT((tblDeliverables[مؤشر الالتزام الزمني]=$AB$2)*((( Dashboard!$I$25="الكل")+(tblDeliverables[التصنيف]=Dashboard!$I$25))>0)*((( Dashboard!$M$25="الكل")+(tblDeliverables[الأولوية]=Dashboard!$M$25))>0)),NA())))))) -> 6
A3: مراجعة المختصين | B3: =COUNTIF(tblDeliverables[الحالة الحالية],"مراجعة المختصين") -> 8 | D3: مجلس الإدارة | E3: =COUNTIF(tblDeliverables[المختص / الجهة المراجعة],"مجلس الإدارة") -> 2 | G3: متوسطة | H3: =COUNTIF(tblDeliverables[الأولوية],"متوسطة") -> 10 | J3: ضمن الخطة | K3: =COUNTIF(tblDeliverables[مؤشر الالتزام الزمني],"ضمن الخطة") -> 20 | M3: قيد العمل | N3: =COUNTA(tblDeliverables[المخرج])-N2 -> 21 | Q3: =IFERROR(IF(INDEX(tblDeliverables[مؤشر الالتزام الزمني],1)="متأخر",INDEX(tblDeliverables[المخرج],1),""),"") | R3: =IFERROR(IF(AND(INDEX(tblDeliverables[الأولوية],1)="عالية",INDEX(tblDeliverables[الحالة الحالية],1)<>"معتمد ونافذ",INDEX(tblDeliverables[المخرج],1)<>""),INDEX(tblDeliverables[المخرج],1),""),"") | S3: =IFERROR(IF(INDEX(tblMeetings[الحالة],1)="مفتوح",INDEX(tblMeetings[أهم القرارات],1),""),"") | T3: =IFERROR(IF(AND(INDEX(tblMeetings[تاريخ الاستحقاق],1)<>"",INDEX(tblMeetings[تاريخ الاستحقاق],1)>=TODAY(),INDEX(tblMeetings[تاريخ الاستحقاق],1)<=TODAY()+14,INDEX(tblMeetings[الحالة],1)<>"مغلق"),INDEX(tblMeetings[الإجراءات المطلوبة],1),""),"") | V3: =Q3 | W3: =R3 | X3: =S3 | Y3: =T3 | AB3: =IFERROR(IF(Dashboard!$E$25="الحالة",INDEX('Lookup Lists'!$A$5:$A$11,2),IF(Dashboard!$E$25="الأولوية",IF(2<=3,INDEX('Lookup Lists'!$B$5:$B$7,2),""),IF(Dashboard!$E$25="التصنيف",IF(2<=4,INDEX('Lookup Lists'!$D$5:$D$8,2),""),IF(Dashboard!$E$25="النطاق",IF(2<=2,INDEX('Lookup Lists'!$K$5:$K$6,2),""),IF(Dashboard!$E$25="الالتزام الزمني",IF(2<=3,INDEX('Lookup Lists'!$J$5:$J$7,2),""),""))))),"") -> مراجعة المختصين | AC3: =IF($AB$3="",NA(),IF(Dashboard!$E$25="الحالة",SUMPRODUCT((tblDeliverables[الحالة الحالية]=$AB$3)*((( Dashboard!$I$25="الكل")+(tblDeliverables[التصنيف]=Dashboard!$I$25))>0)*((( Dashboard!$M$25="الكل")+(tblDeliverables[الأولوية]=Dashboard!$M$25))>0)),IF(Dashboard!$E$25="الأولوية",SUMPRODUCT((tblDeliverables[الأولوية]=$AB$3)*((( Dashboard!$I$25="الكل")+(tblDeliverables[التصنيف]=Dashboard!$I$25))>0)),IF(Dashboard!$E$25="التصنيف",SUMPRODUCT((tblDeliverables[التصنيف]=$AB$3)*((( Dashboard!$M$25="الكل")+(tblDeliverables[الأولوية]=Dashboard!$M$25))>0)),IF(Dashboard!$E$25="النطاق",SUMPRODUCT((tblDeliverables[النطاق]=$AB$3)*((( Dashboard!$I$25="الكل")+(tblDeliverables[التصنيف]=Dashboard!$I$25))>0)*((( Dashboard!$M$25="الكل")+(tblDeliverables[الأولوية]=Dashboard!$M$25))>0)),IF(Dashboard!$E$25="الالتزام الزمني",SUMPRODUCT((tblDeliverables[مؤشر الالتزام الزمني]=$AB$3)*((( Dashboard!$I$25="الكل")+(tblDeliverables[التصنيف]=Dashboard!$I$25))>0)*((( Dashboard!$M$25="الكل")+(tblDeliverables[الأولوية]=Dashboard!$M$25))>0)),NA())))))) -> 8
A4: التعديل لدى الحلول القانونية | B4: =COUNTIF(tblDeliverables[الحالة الحالية],"التعديل لدى الحلول القانونية") -> 3 | D4: لجنة المراجعة | E4: =COUNTIF(tblDeliverables[المختص / الجهة المراجعة],"لجنة المراجعة") -> 1 | G4: منخفضة | H4: =COUNTIF(tblDeliverables[الأولوية],"منخفضة") -> 2 | J4: مكتمل | K4: =COUNTIF(tblDeliverables[مؤشر الالتزام الزمني],"مكتمل") -> 1 | Q4: =IFERROR(IF(INDEX(tblDeliverables[مؤشر الالتزام الزمني],2)="متأخر",INDEX(tblDeliverables[المخرج],2),""),"") | R4: =IFERROR(IF(AND(INDEX(tblDeliverables[الأولوية],2)="عالية",INDEX(tblDeliverables[الحالة الحالية],2)<>"معتمد ونافذ",INDEX(tblDeliverables[المخرج],2)<>""),INDEX(tblDeliverables[المخرج],2),""),"") -> لائحة مجلس الإدارة | S4: =IFERROR(IF(INDEX(tblMeetings[الحالة],2)="مفتوح",INDEX(tblMeetings[أهم القرارات],2),""),"") | T4: =IFERROR(IF(AND(INDEX(tblMeetings[تاريخ الاستحقاق],2)<>"",INDEX(tblMeetings[تاريخ الاستحقاق],2)>=TODAY(),INDEX(tblMeetings[تاريخ الاستحقاق],2)<=TODAY()+14,INDEX(tblMeetings[الحالة],2)<>"مغلق"),INDEX(tblMeetings[الإجراءات المطلوبة],2),""),"") | V4: =IF(Q4="",V3,IF(V3="",Q4,V3&"، "&Q4)) | W4: =IF(R4="",W3,IF(W3="",R4,W3&"، "&R4)) -> لائحة مجلس الإدارة | X4: =IF(S4="",X3,IF(X3="",S4,X3&"، "&S4)) | Y4: =IF(T4="",Y3,IF(Y3="",T4,Y3&"، "&T4)) | AB4: =IFERROR(IF(Dashboard!$E$25="الحالة",INDEX('Lookup Lists'!$A$5:$A$11,3),IF(Dashboard!$E$25="الأولوية",IF(3<=3,INDEX('Lookup Lists'!$B$5:$B$7,3),""),IF(Dashboard!$E$25="التصنيف",IF(3<=4,INDEX('Lookup Lists'!$D$5:$D$8,3),""),IF(Dashboard!$E$25="النطاق",IF(3<=2,INDEX('Lookup Lists'!$K$5:$K$6,3),""),IF(Dashboard!$E$25="الالتزام الزمني",IF(3<=3,INDEX('Lookup Lists'!$J$5:$J$7,3),""),""))))),"") -> التعديل لدى الحلول القانونية | AC4: =IF($AB$4="",NA(),IF(Dashboard!$E$25="الحالة",SUMPRODUCT((tblDeliverables[الحالة الحالية]=$AB$4)*((( Dashboard!$I$25="الكل")+(tblDeliverables[التصنيف]=Dashboard!$I$25))>0)*((( Dashboard!$M$25="الكل")+(tblDeliverables[الأولوية]=Dashboard!$M$25))>0)),IF(Dashboard!$E$25="الأولوية",SUMPRODUCT((tblDeliverables[الأولوية]=$AB$4)*((( Dashboard!$I$25="الكل")+(tblDeliverables[التصنيف]=Dashboard!$I$25))>0)),IF(Dashboard!$E$25="التصنيف",SUMPRODUCT((tblDeliverables[التصنيف]=$AB$4)*((( Dashboard!$M$25="الكل")+(tblDeliverables[الأولوية]=Dashboard!$M$25))>0)),IF(Dashboard!$E$25="النطاق",SUMPRODUCT((tblDeliverables[النطاق]=$AB$4)*((( Dashboard!$I$25="الكل")+(tblDeliverables[التصنيف]=Dashboard!$I$25))>0)*((( Dashboard!$M$25="الكل")+(tblDeliverables[الأولوية]=Dashboard!$M$25))>0)),IF(Dashboard!$E$25="الالتزام الزمني",SUMPRODUCT((tblDeliverables[مؤشر الالتزام الزمني]=$AB$4)*((( Dashboard!$I$25="الكل")+(tblDeliverables[التصنيف]=Dashboard!$I$25))>0)*((( Dashboard!$M$25="الكل")+(tblDeliverables[الأولوية]=Dashboard!$M$25))>0)),NA())))))) -> 3
A5: مراجعة لجنة الحوكمة | B5: =COUNTIF(tblDeliverables[الحالة الحالية],"مراجعة لجنة الحوكمة") -> 2 | D5: لجنة الترشيحات والمكافآت | E5: =COUNTIF(tblDeliverables[المختص / الجهة المراجعة],"لجنة الترشيحات والمكافآت") -> 1 | Q5: =IFERROR(IF(INDEX(tblDeliverables[مؤشر الالتزام الزمني],3)="متأخر",INDEX(tblDeliverables[المخرج],3),""),"") | R5: =IFERROR(IF(AND(INDEX(tblDeliverables[الأولوية],3)="عالية",INDEX(tblDeliverables[الحالة الحالية],3)<>"معتمد ونافذ",INDEX(tblDeliverables[المخرج],3)<>""),INDEX(tblDeliverables[المخرج],3),""),"") -> لائحة لجنة المراجعة | S5: =IFERROR(IF(INDEX(tblMeetings[الحالة],3)="مفتوح",INDEX(tblMeetings[أهم القرارات],3),""),"") -> مراجعة حالة المخرجات المتأخرة | T5: =IFERROR(IF(AND(INDEX(tblMeetings[تاريخ الاستحقاق],3)<>"",INDEX(tblMeetings[تاريخ الاستحقاق],3)>=TODAY(),INDEX(tblMeetings[تاريخ الاستحقاق],3)<=TODAY()+14,INDEX(tblMeetings[الحالة],3)<>"مغلق"),INDEX(tblMeetings[الإجراءات المطلوبة],3),""),"") -> تسريع اعتماد مصفوفة الصلاحيات الشاملة | V5: =IF(Q5="",V4,IF(V4="",Q5,V4&"، "&Q5)) | W5: =IF(R5="",W4,IF(W4="",R5,W4&"، "&R5)) -> لائحة مجلس الإدارة، لائحة لجنة المراجعة | X5: =IF(S5="",X4,IF(X4="",S5,X4&"، "&S5)) -> مراجعة حالة المخرجات المتأخرة | Y5: =IF(T5="",Y4,IF(Y4="",T5,Y4&"، "&T5)) -> تسريع اعتماد مصفوفة الصلاحيات الشاملة | AB5: =IFERROR(IF(Dashboard!$E$25="الحالة",INDEX('Lookup Lists'!$A$5:$A$11,4),IF(Dashboard!$E$25="الأولوية",IF(4<=3,INDEX('Lookup Lists'!$B$5:$B$7,4),""),IF(Dashboard!$E$25="التصنيف",IF(4<=4,INDEX('Lookup Lists'!$D$5:$D$8,4),""),IF(Dashboard!$E$25="النطاق",IF(4<=2,INDEX('Lookup Lists'!$K$5:$K$6,4),""),IF(Dashboard!$E$25="الالتزام الزمني",IF(4<=3,INDEX('Lookup Lists'!$J$5:$J$7,4),""),""))))),"") -> مراجعة لجنة الحوكمة | AC5: =IF($AB$5="",NA(),IF(Dashboard!$E$25="الحالة",SUMPRODUCT((tblDeliverables[الحالة الحالية]=$AB$5)*((( Dashboard!$I$25="الكل")+(tblDeliverables[التصنيف]=Dashboard!$I$25))>0)*((( Dashboard!$M$25="الكل")+(tblDeliverables[الأولوية]=Dashboard!$M$25))>0)),IF(Dashboard!$E$25="الأولوية",SUMPRODUCT((tblDeliverables[الأولوية]=$AB$5)*((( Dashboard!$I$25="الكل")+(tblDeliverables[التصنيف]=Dashboard!$I$25))>0)),IF(Dashboard!$E$25="التصنيف",SUMPRODUCT((tblDeliverables[التصنيف]=$AB$5)*((( Dashboard!$M$25="الكل")+(tblDeliverables[الأولوية]=Dashboard!$M$25))>0)),IF(Dashboard!$E$25="النطاق",SUMPRODUCT((tblDeliverables[النطاق]=$AB$5)*((( Dashboard!$I$25="الكل")+(tblDeliverables[التصنيف]=Dashboard!$I$25))>0)*((( Dashboard!$M$25="الكل")+(tblDeliverables[الأولوية]=Dashboard!$M$25))>0)),IF(Dashboard!$E$25="الالتزام الزمني",SUMPRODUCT((tblDeliverables[مؤشر الالتزام الزمني]=$AB$5)*((( Dashboard!$I$25="الكل")+(tblDeliverables[التصنيف]=Dashboard!$I$25))>0)*((( Dashboard!$M$25="الكل")+(tblDeliverables[الأولوية]=Dashboard!$M$25))>0)),NA())))))) -> 2
A6: مراجعة لجنة الترشيحات والمكافآت | B6: =COUNTIF(tblDeliverables[الحالة الحالية],"مراجعة لجنة الترشيحات والمكافآت") -> 1 | D6: الرئيس التنفيذي | E6: =COUNTIF(tblDeliverables[المختص / الجهة المراجعة],"الرئيس التنفيذي") -> 4 | Q6: =IFERROR(IF(INDEX(tblDeliverables[مؤشر الالتزام الزمني],4)="متأخر",INDEX(tblDeliverables[المخرج],4),""),"") | R6: =IFERROR(IF(AND(INDEX(tblDeliverables[الأولوية],4)="عالية",INDEX(tblDeliverables[الحالة الحالية],4)<>"معتمد ونافذ",INDEX(tblDeliverables[المخرج],4)<>""),INDEX(tblDeliverables[المخرج],4),""),"") -> لائحة لجنة الترشيحات والمكافآت | S6: =IFERROR(IF(INDEX(tblMeetings[الحالة],4)="مفتوح",INDEX(tblMeetings[أهم القرارات],4),""),"") -> الموافقة على رفع لوائح اللجان للمجلس | T6: =IFERROR(IF(AND(INDEX(tblMeetings[تاريخ الاستحقاق],4)<>"",INDEX(tblMeetings[تاريخ الاستحقاق],4)>=TODAY(),INDEX(tblMeetings[تاريخ الاستحقاق],4)<=TODAY()+14,INDEX(tblMeetings[الحالة],4)<>"مغلق"),INDEX(tblMeetings[الإجراءات المطلوبة],4),""),"") -> جدولة جلسة اعتماد لائحة مجلس الإدارة | V6: =IF(Q6="",V5,IF(V5="",Q6,V5&"، "&Q6)) | W6: =IF(R6="",W5,IF(W5="",R6,W5&"، "&R6)) -> لائحة مجلس الإدارة، لائحة لجنة المراجعة، لائحة لجنة الترشيحات والمكافآت | X6: =IF(S6="",X5,IF(X5="",S6,X5&"، "&S6)) -> مراجعة حالة المخرجات المتأخرة، الموافقة على رفع لوائح اللجان للمجلس | Y6: =IF(T6="",Y5,IF(Y5="",T6,Y5&"، "&T6)) -> تسريع اعتماد مصفوفة الصلاحيات الشاملة، جدولة جلسة اعتماد لائحة مجلس الإدارة | AB6: =IFERROR(IF(Dashboard!$E$25="الحالة",INDEX('Lookup Lists'!$A$5:$A$11,5),IF(Dashboard!$E$25="الأولوية",IF(5<=3,INDEX('Lookup Lists'!$B$5:$B$7,5),""),IF(Dashboard!$E$25="التصنيف",IF(5<=4,INDEX('Lookup Lists'!$D$5:$D$8,5),""),IF(Dashboard!$E$25="النطاق",IF(5<=2,INDEX('Lookup Lists'!$K$5:$K$6,5),""),IF(Dashboard!$E$25="الالتزام الزمني",IF(5<=3,INDEX('Lookup Lists'!$J$5:$J$7,5),""),""))))),"") -> مراجعة لجنة الترشيحات والمكافآت | AC6: =IF($AB$6="",NA(),IF(Dashboard!$E$25="الحالة",SUMPRODUCT((tblDeliverables[الحالة الحالية]=$AB$6)*((( Dashboard!$I$25="الكل")+(tblDeliverables[التصنيف]=Dashboard!$I$25))>0)*((( Dashboard!$M$25="الكل")+(tblDeliverables[الأولوية]=Dashboard!$M$25))>0)),IF(Dashboard!$E$25="الأولوية",SUMPRODUCT((tblDeliverables[الأولوية]=$AB$6)*((( Dashboard!$I$25="الكل")+(tblDeliverables[التصنيف]=Dashboard!$I$25))>0)),IF(Dashboard!$E$25="التصنيف",SUMPRODUCT((tblDeliverables[التصنيف]=$AB$6)*((( Dashboard!$M$25="الكل")+(tblDeliverables[الأولوية]=Dashboard!$M$25))>0)),IF(Dashboard!$E$25="النطاق",SUMPRODUCT((tblDeliverables[النطاق]=$AB$6)*((( Dashboard!$I$25="الكل")+(tblDeliverables[التصنيف]=Dashboard!$I$25))>0)*((( Dashboard!$M$25="الكل")+(tblDeliverables[الأولوية]=Dashboard!$M$25))>0)),IF(Dashboard!$E$25="الالتزام الزمني",SUMPRODUCT((tblDeliverables[مؤشر الالتزام الزمني]=$AB$6)*((( Dashboard!$I$25="الكل")+(tblDeliverables[التصنيف]=Dashboard!$I$25))>0)*((( Dashboard!$M$25="الكل")+(tblDeliverables[الأولوية]=Dashboard!$M$25))>0)),NA())))))) -> 1
A7: اعتماد مجلس الإدارة | B7: =COUNTIF(tblDeliverables[الحالة الحالية],"اعتماد مجلس الإدارة") -> 1 | D7: الإدارة التنفيذية | E7: =COUNTIF(tblDeliverables[المختص / الجهة المراجعة],"الإدارة التنفيذية") -> 3 | Q7: =IFERROR(IF(INDEX(tblDeliverables[مؤشر الالتزام الزمني],5)="متأخر",INDEX(tblDeliverables[المخرج],5),""),"") | R7: =IFERROR(IF(AND(INDEX(tblDeliverables[الأولوية],5)="عالية",INDEX(tblDeliverables[الحالة الحالية],5)<>"معتمد ونافذ",INDEX(tblDeliverables[المخرج],5)<>""),INDEX(tblDeliverables[المخرج],5),""),"") | S7: =IFERROR(IF(INDEX(tblMeetings[الحالة],5)="مفتوح",INDEX(tblMeetings[أهم القرارات],5),""),"") | T7: =IFERROR(IF(AND(INDEX(tblMeetings[تاريخ الاستحقاق],5)<>"",INDEX(tblMeetings[تاريخ الاستحقاق],5)>=TODAY(),INDEX(tblMeetings[تاريخ الاستحقاق],5)<=TODAY()+14,INDEX(tblMeetings[الحالة],5)<>"مغلق"),INDEX(tblMeetings[الإجراءات المطلوبة],5),""),"") | V7: =IF(Q7="",V6,IF(V6="",Q7,V6&"، "&Q7)) | W7: =IF(R7="",W6,IF(W6="",R7,W6&"، "&R7)) -> لائحة مجلس الإدارة، لائحة لجنة المراجعة، لائحة لجنة الترشيحات والمكافآت | X7: =IF(S7="",X6,IF(X6="",S7,X6&"، "&S7)) -> مراجعة حالة المخرجات المتأخرة، الموافقة على رفع لوائح اللجان للمجلس | Y7: =IF(T7="",Y6,IF(Y6="",T7,Y6&"، "&T7)) -> تسريع اعتماد مصفوفة الصلاحيات الشاملة، جدولة جلسة اعتماد لائحة مجلس الإدارة | AB7: =IFERROR(IF(Dashboard!$E$25="الحالة",INDEX('Lookup Lists'!$A$5:$A$11,6),IF(Dashboard!$E$25="الأولوية",IF(6<=3,INDEX('Lookup Lists'!$B$5:$B$7,6),""),IF(Dashboard!$E$25="التصنيف",IF(6<=4,INDEX('Lookup Lists'!$D$5:$D$8,6),""),IF(Dashboard!$E$25="النطاق",IF(6<=2,INDEX('Lookup Lists'!$K$5:$K$6,6),""),IF(Dashboard!$E$25="الالتزام الزمني",IF(6<=3,INDEX('Lookup Lists'!$J$5:$J$7,6),""),""))))),"") -> اعتماد مجلس الإدارة | AC7: =IF($AB$7="",NA(),IF(Dashboard!$E$25="الحالة",SUMPRODUCT((tblDeliverables[الحالة الحالية]=$AB$7)*((( Dashboard!$I$25="الكل")+(tblDeliverables[التصنيف]=Dashboard!$I$25))>0)*((( Dashboard!$M$25="الكل")+(tblDeliverables[الأولوية]=Dashboard!$M$25))>0)),IF(Dashboard!$E$25="الأولوية",SUMPRODUCT((tblDeliverables[الأولوية]=$AB$7)*((( Dashboard!$I$25="الكل")+(tblDeliverables[التصنيف]=Dashboard!$I$25))>0)),IF(Dashboard!$E$25="التصنيف",SUMPRODUCT((tblDeliverables[التصنيف]=$AB$7)*((( Dashboard!$M$25="الكل")+(tblDeliverables[الأولوية]=Dashboard!$M$25))>0)),IF(Dashboard!$E$25="النطاق",SUMPRODUCT((tblDeliverables[النطاق]=$AB$7)*((( Dashboard!$I$25="الكل")+(tblDeliverables[التصنيف]=Dashboard!$I$25))>0)*((( Dashboard!$M$25="الكل")+(tblDeliverables[الأولوية]=Dashboard!$M$25))>0)),IF(Dashboard!$E$25="الالتزام الزمني",SUMPRODUCT((tblDeliverables[مؤشر الالتزام الزمني]=$AB$7)*((( Dashboard!$I$25="الكل")+(tblDeliverables[التصنيف]=Dashboard!$I$25))>0)*((( Dashboard!$M$25="الكل")+(tblDeliverables[الأولوية]=Dashboard!$M$25))>0)),NA())))))) -> 1
A8: معتمد ونافذ | B8: =COUNTIF(tblDeliverables[الحالة الحالية],"معتمد ونافذ") -> 1 | D8: عامر البيروتي | E8: =COUNTIF(tblDeliverables[المختص / الجهة المراجعة],"عامر البيروتي") -> 0 | Q8: =IFERROR(IF(INDEX(tblDeliverables[مؤشر الالتزام الزمني],6)="متأخر",INDEX(tblDeliverables[المخرج],6),""),"") | R8: =IFERROR(IF(AND(INDEX(tblDeliverables[الأولوية],6)="عالية",INDEX(tblDeliverables[الحالة الحالية],6)<>"معتمد ونافذ",INDEX(tblDeliverables[المخرج],6)<>""),INDEX(tblDeliverables[المخرج],6),""),"") | S8: =IFERROR(IF(INDEX(tblMeetings[الحالة],6)="مفتوح",INDEX(tblMeetings[أهم القرارات],6),""),"") | T8: =IFERROR(IF(AND(INDEX(tblMeetings[تاريخ الاستحقاق],6)<>"",INDEX(tblMeetings[تاريخ الاستحقاق],6)>=TODAY(),INDEX(tblMeetings[تاريخ الاستحقاق],6)<=TODAY()+14,INDEX(tblMeetings[الحالة],6)<>"مغلق"),INDEX(tblMeetings[الإجراءات المطلوبة],6),""),"") | V8: =IF(Q8="",V7,IF(V7="",Q8,V7&"، "&Q8)) | W8: =IF(R8="",W7,IF(W7="",R8,W7&"، "&R8)) -> لائحة مجلس الإدارة، لائحة لجنة المراجعة، لائحة لجنة الترشيحات والمكافآت | X8: =IF(S8="",X7,IF(X7="",S8,X7&"، "&S8)) -> مراجعة حالة المخرجات المتأخرة، الموافقة على رفع لوائح اللجان للمجلس | Y8: =IF(T8="",Y7,IF(Y7="",T8,Y7&"، "&T8)) -> تسريع اعتماد مصفوفة الصلاحيات الشاملة، جدولة جلسة اعتماد لائحة مجلس الإدارة | AB8: =IFERROR(IF(Dashboard!$E$25="الحالة",INDEX('Lookup Lists'!$A$5:$A$11,7),IF(Dashboard!$E$25="الأولوية",IF(7<=3,INDEX('Lookup Lists'!$B$5:$B$7,7),""),IF(Dashboard!$E$25="التصنيف",IF(7<=4,INDEX('Lookup Lists'!$D$5:$D$8,7),""),IF(Dashboard!$E$25="النطاق",IF(7<=2,INDEX('Lookup Lists'!$K$5:$K$6,7),""),IF(Dashboard!$E$25="الالتزام الزمني",IF(7<=3,INDEX('Lookup Lists'!$J$5:$J$7,7),""),""))))),"") -> معتمد ونافذ | AC8: =IF($AB$8="",NA(),IF(Dashboard!$E$25="الحالة",SUMPRODUCT((tblDeliverables[الحالة الحالية]=$AB$8)*((( Dashboard!$I$25="الكل")+(tblDeliverables[التصنيف]=Dashboard!$I$25))>0)*((( Dashboard!$M$25="الكل")+(tblDeliverables[الأولوية]=Dashboard!$M$25))>0)),IF(Dashboard!$E$25="الأولوية",SUMPRODUCT((tblDeliverables[الأولوية]=$AB$8)*((( Dashboard!$I$25="الكل")+(tblDeliverables[التصنيف]=Dashboard!$I$25))>0)),IF(Dashboard!$E$25="التصنيف",SUMPRODUCT((tblDeliverables[التصنيف]=$AB$8)*((( Dashboard!$M$25="الكل")+(tblDeliverables[الأولوية]=Dashboard!$M$25))>0)),IF(Dashboard!$E$25="النطاق",SUMPRODUCT((tblDeliverables[النطاق]=$AB$8)*((( Dashboard!$I$25="الكل")+(tblDeliverables[التصنيف]=Dashboard!$I$25))>0)*((( Dashboard!$M$25="الكل")+(tblDeliverables[الأولوية]=Dashboard!$M$25))>0)),IF(Dashboard!$E$25="الالتزام الزمني",SUMPRODUCT((tblDeliverables[مؤشر الالتزام الزمني]=$AB$8)*((( Dashboard!$I$25="الكل")+(tblDeliverables[التصنيف]=Dashboard!$I$25))>0)*((( Dashboard!$M$25="الكل")+(tblDeliverables[الأولوية]=Dashboard!$M$25))>0)),NA())))))) -> 1
D9: أمين المجلس | E9: =COUNTIF(tblDeliverables[المختص / الجهة المراجعة],"أمين المجلس") -> 0 | Q9: =IFERROR(IF(INDEX(tblDeliverables[مؤشر الالتزام الزمني],7)="متأخر",INDEX(tblDeliverables[المخرج],7),""),"") | R9: =IFERROR(IF(AND(INDEX(tblDeliverables[الأولوية],7)="عالية",INDEX(tblDeliverables[الحالة الحالية],7)<>"معتمد ونافذ",INDEX(tblDeliverables[المخرج],7)<>""),INDEX(tblDeliverables[المخرج],7),""),"") | S9: =IFERROR(IF(INDEX(tblMeetings[الحالة],7)="مفتوح",INDEX(tblMeetings[أهم القرارات],7),""),"") | T9: =IFERROR(IF(AND(INDEX(tblMeetings[تاريخ الاستحقاق],7)<>"",INDEX(tblMeetings[تاريخ الاستحقاق],7)>=TODAY(),INDEX(tblMeetings[تاريخ الاستحقاق],7)<=TODAY()+14,INDEX(tblMeetings[الحالة],7)<>"مغلق"),INDEX(tblMeetings[الإجراءات المطلوبة],7),""),"") | V9: =IF(Q9="",V8,IF(V8="",Q9,V8&"، "&Q9)) | W9: =IF(R9="",W8,IF(W8="",R9,W8&"، "&R9)) -> لائحة مجلس الإدارة، لائحة لجنة المراجعة، لائحة لجنة الترشيحات والمكافآت | X9: =IF(S9="",X8,IF(X8="",S9,X8&"، "&S9)) -> مراجعة حالة المخرجات المتأخرة، الموافقة على رفع لوائح اللجان للمجلس | Y9: =IF(T9="",Y8,IF(Y8="",T9,Y8&"، "&T9)) -> تسريع اعتماد مصفوفة الصلاحيات الشاملة، جدولة جلسة اعتماد لائحة مجلس الإدارة
D10: الموارد البشرية | E10: =COUNTIF(tblDeliverables[المختص / الجهة المراجعة],"الموارد البشرية") -> 0 | Q10: =IFERROR(IF(INDEX(tblDeliverables[مؤشر الالتزام الزمني],8)="متأخر",INDEX(tblDeliverables[المخرج],8),""),"") | R10: =IFERROR(IF(AND(INDEX(tblDeliverables[الأولوية],8)="عالية",INDEX(tblDeliverables[الحالة الحالية],8)<>"معتمد ونافذ",INDEX(tblDeliverables[المخرج],8)<>""),INDEX(tblDeliverables[المخرج],8),""),"") | S10: =IFERROR(IF(INDEX(tblMeetings[الحالة],8)="مفتوح",INDEX(tblMeetings[أهم القرارات],8),""),"") | T10: =IFERROR(IF(AND(INDEX(tblMeetings[تاريخ الاستحقاق],8)<>"",INDEX(tblMeetings[تاريخ الاستحقاق],8)>=TODAY(),INDEX(tblMeetings[تاريخ الاستحقاق],8)<=TODAY()+14,INDEX(tblMeetings[الحالة],8)<>"مغلق"),INDEX(tblMeetings[الإجراءات المطلوبة],8),""),"") | V10: =IF(Q10="",V9,IF(V9="",Q10,V9&"، "&Q10)) | W10: =IF(R10="",W9,IF(W9="",R10,W9&"، "&R10)) -> لائحة مجلس الإدارة، لائحة لجنة المراجعة، لائحة لجنة الترشيحات والمكافآت | X10: =IF(S10="",X9,IF(X9="",S10,X9&"، "&S10)) -> مراجعة حالة المخرجات المتأخرة، الموافقة على رفع لوائح اللجان للمجلس | Y10: =IF(T10="",Y9,IF(Y9="",T10,Y9&"، "&T10)) -> تسريع اعتماد مصفوفة الصلاحيات الشاملة، جدولة جلسة اعتماد لائحة مجلس الإدارة
D11: الإدارة المالية | E11: =COUNTIF(tblDeliverables[المختص / الجهة المراجعة],"الإدارة المالية") -> 3 | Q11: =IFERROR(IF(INDEX(tblDeliverables[مؤشر الالتزام الزمني],9)="متأخر",INDEX(tblDeliverables[المخرج],9),""),"") -> مصفوفة الصلاحيات الشاملة | R11: =IFERROR(IF(AND(INDEX(tblDeliverables[الأولوية],9)="عالية",INDEX(tblDeliverables[الحالة الحالية],9)<>"معتمد ونافذ",INDEX(tblDeliverables[المخرج],9)<>""),INDEX(tblDeliverables[المخرج],9),""),"") -> مصفوفة الصلاحيات الشاملة | S11: =IFERROR(IF(INDEX(tblMeetings[الحالة],9)="مفتوح",INDEX(tblMeetings[أهم القرارات],9),""),"") | T11: =IFERROR(IF(AND(INDEX(tblMeetings[تاريخ الاستحقاق],9)<>"",INDEX(tblMeetings[تاريخ الاستحقاق],9)>=TODAY(),INDEX(tblMeetings[تاريخ الاستحقاق],9)<=TODAY()+14,INDEX(tblMeetings[الحالة],9)<>"مغلق"),INDEX(tblMeetings[الإجراءات المطلوبة],9),""),"") | V11: =IF(Q11="",V10,IF(V10="",Q11,V10&"، "&Q11)) -> مصفوفة الصلاحيات الشاملة | W11: =IF(R11="",W10,IF(W10="",R11,W10&"، "&R11)) -> لائحة مجلس الإدارة، لائحة لجنة المراجعة، لائحة لجنة الترشيحات والمكافآت، مصفوفة الصلاحيات الشاملة | X11: =IF(S11="",X10,IF(X10="",S11,X10&"، "&S11)) -> مراجعة حالة المخرجات المتأخرة، الموافقة على رفع لوائح اللجان للمجلس | Y11: =IF(T11="",Y10,IF(Y10="",T11,Y10&"، "&T11)) -> تسريع اعتماد مصفوفة الصلاحيات الشاملة، جدولة جلسة اعتماد لائحة مجلس الإدارة
D12: تقنية المعلومات | E12: =COUNTIF(tblDeliverables[المختص / الجهة المراجعة],"تقنية المعلومات") -> 1 | Q12: =IFERROR(IF(INDEX(tblDeliverables[مؤشر الالتزام الزمني],10)="متأخر",INDEX(tblDeliverables[المخرج],10),""),"") | R12: =IFERROR(IF(AND(INDEX(tblDeliverables[الأولوية],10)="عالية",INDEX(tblDeliverables[الحالة الحالية],10)<>"معتمد ونافذ",INDEX(tblDeliverables[المخرج],10)<>""),INDEX(tblDeliverables[المخرج],10),""),"") | S12: =IFERROR(IF(INDEX(tblMeetings[الحالة],10)="مفتوح",INDEX(tblMeetings[أهم القرارات],10),""),"") | T12: =IFERROR(IF(AND(INDEX(tblMeetings[تاريخ الاستحقاق],10)<>"",INDEX(tblMeetings[تاريخ الاستحقاق],10)>=TODAY(),INDEX(tblMeetings[تاريخ الاستحقاق],10)<=TODAY()+14,INDEX(tblMeetings[الحالة],10)<>"مغلق"),INDEX(tblMeetings[الإجراءات المطلوبة],10),""),"") | V12: =IF(Q12="",V11,IF(V11="",Q12,V11&"، "&Q12)) -> مصفوفة الصلاحيات الشاملة | W12: =IF(R12="",W11,IF(W11="",R12,W11&"، "&R12)) -> لائحة مجلس الإدارة، لائحة لجنة المراجعة، لائحة لجنة الترشيحات والمكافآت، مصفوفة الصلاحيات الشاملة | X12: =IF(S12="",X11,IF(X11="",S12,X11&"، "&S12)) -> مراجعة حالة المخرجات المتأخرة، الموافقة على رفع لوائح اللجان للمجلس | Y12: =IF(T12="",Y11,IF(Y11="",T12,Y11&"، "&T12)) -> تسريع اعتماد مصفوفة الصلاحيات الشاملة، جدولة جلسة اعتماد لائحة مجلس الإدارة
D13: الشؤون القانونية | E13: =COUNTIF(tblDeliverables[المختص / الجهة المراجعة],"الشؤون القانونية") -> 5 | Q13: =IFERROR(IF(INDEX(tblDeliverables[مؤشر الالتزام الزمني],11)="متأخر",INDEX(tblDeliverables[المخرج],11),""),"") | R13: =IFERROR(IF(AND(INDEX(tblDeliverables[الأولوية],11)="عالية",INDEX(tblDeliverables[الحالة الحالية],11)<>"معتمد ونافذ",INDEX(tblDeliverables[المخرج],11)<>""),INDEX(tblDeliverables[المخرج],11),""),"") -> سياسة تعارض المصالح | S13: =IFERROR(IF(INDEX(tblMeetings[الحالة],11)="مفتوح",INDEX(tblMeetings[أهم القرارات],11),""),"") | T13: =IFERROR(IF(AND(INDEX(tblMeetings[تاريخ الاستحقاق],11)<>"",INDEX(tblMeetings[تاريخ الاستحقاق],11)>=TODAY(),INDEX(tblMeetings[تاريخ الاستحقاق],11)<=TODAY()+14,INDEX(tblMeetings[الحالة],11)<>"مغلق"),INDEX(tblMeetings[الإجراءات المطلوبة],11),""),"") | V13: =IF(Q13="",V12,IF(V12="",Q13,V12&"، "&Q13)) -> مصفوفة الصلاحيات الشاملة | W13: =IF(R13="",W12,IF(W12="",R13,W12&"، "&R13)) -> لائحة مجلس الإدارة، لائحة لجنة المراجعة، لائحة لجنة الترشيحات والمكافآت، مصفوفة الصلاحيات الشاملة، سياسة تعارض المصالح | X13: =IF(S13="",X12,IF(X12="",S13,X12&"، "&S13)) -> مراجعة حالة المخرجات المتأخرة، الموافقة على رفع لوائح اللجان للمجلس | Y13: =IF(T13="",Y12,IF(Y12="",T13,Y12&"، "&T13)) -> تسريع اعتماد مصفوفة الصلاحيات الشاملة، جدولة جلسة اعتماد لائحة مجلس الإدارة
D14: الإدارة التجارية | E14: =COUNTIF(tblDeliverables[المختص / الجهة المراجعة],"الإدارة التجارية") -> 0 | Q14: =IFERROR(IF(INDEX(tblDeliverables[مؤشر الالتزام الزمني],12)="متأخر",INDEX(tblDeliverables[المخرج],12),""),"") | R14: =IFERROR(IF(AND(INDEX(tblDeliverables[الأولوية],12)="عالية",INDEX(tblDeliverables[الحالة الحالية],12)<>"معتمد ونافذ",INDEX(tblDeliverables[المخرج],12)<>""),INDEX(tblDeliverables[المخرج],12),""),"") -> سياسة إدارة المخاطر | S14: =IFERROR(IF(INDEX(tblMeetings[الحالة],12)="مفتوح",INDEX(tblMeetings[أهم القرارات],12),""),"") | T14: =IFERROR(IF(AND(INDEX(tblMeetings[تاريخ الاستحقاق],12)<>"",INDEX(tblMeetings[تاريخ الاستحقاق],12)>=TODAY(),INDEX(tblMeetings[تاريخ الاستحقاق],12)<=TODAY()+14,INDEX(tblMeetings[الحالة],12)<>"مغلق"),INDEX(tblMeetings[الإجراءات المطلوبة],12),""),"") | V14: =IF(Q14="",V13,IF(V13="",Q14,V13&"، "&Q14)) -> مصفوفة الصلاحيات الشاملة | W14: =IF(R14="",W13,IF(W13="",R14,W13&"، "&R14)) -> لائحة مجلس الإدارة، لائحة لجنة المراجعة، لائحة لجنة الترشيحات والمكافآت، مصفوفة الصلاحيات الشاملة، سياسة تعارض المصالح، سياسة إدارة المخاطر | X14: =IF(S14="",X13,IF(X13="",S14,X13&"، "&S14)) -> مراجعة حالة المخرجات المتأخرة، الموافقة على رفع لوائح اللجان للمجلس | Y14: =IF(T14="",Y13,IF(Y13="",T14,Y13&"، "&T14)) -> تسريع اعتماد مصفوفة الصلاحيات الشاملة، جدولة جلسة اعتماد لائحة مجلس الإدارة
D15: العمليات والتشغيل | E15: =COUNTIF(tblDeliverables[المختص / الجهة المراجعة],"العمليات والتشغيل") -> 1 | Q15: =IFERROR(IF(INDEX(tblDeliverables[مؤشر الالتزام الزمني],13)="متأخر",INDEX(tblDeliverables[المخرج],13),""),"") | R15: =IFERROR(IF(AND(INDEX(tblDeliverables[الأولوية],13)="عالية",INDEX(tblDeliverables[الحالة الحالية],13)<>"معتمد ونافذ",INDEX(tblDeliverables[المخرج],13)<>""),INDEX(tblDeliverables[المخرج],13),""),"") | S15: =IFERROR(IF(INDEX(tblMeetings[الحالة],13)="مفتوح",INDEX(tblMeetings[أهم القرارات],13),""),"") | T15: =IFERROR(IF(AND(INDEX(tblMeetings[تاريخ الاستحقاق],13)<>"",INDEX(tblMeetings[تاريخ الاستحقاق],13)>=TODAY(),INDEX(tblMeetings[تاريخ الاستحقاق],13)<=TODAY()+14,INDEX(tblMeetings[الحالة],13)<>"مغلق"),INDEX(tblMeetings[الإجراءات المطلوبة],13),""),"") | V15: =IF(Q15="",V14,IF(V14="",Q15,V14&"، "&Q15)) -> مصفوفة الصلاحيات الشاملة | W15: =IF(R15="",W14,IF(W14="",R15,W14&"، "&R15)) -> لائحة مجلس الإدارة، لائحة لجنة المراجعة، لائحة لجنة الترشيحات والمكافآت، مصفوفة الصلاحيات الشاملة، سياسة تعارض المصالح، سياسة إدارة المخاطر | X15: =IF(S15="",X14,IF(X14="",S15,X14&"، "&S15)) -> مراجعة حالة المخرجات المتأخرة، الموافقة على رفع لوائح اللجان للمجلس | Y15: =IF(T15="",Y14,IF(Y14="",T15,Y14&"، "&T15)) -> تسريع اعتماد مصفوفة الصلاحيات الشاملة، جدولة جلسة اعتماد لائحة مجلس الإدارة
D16: المشتريات والمستودعات | E16: =COUNTIF(tblDeliverables[المختص / الجهة المراجعة],"المشتريات والمستودعات") -> 0 | Q16: =IFERROR(IF(INDEX(tblDeliverables[مؤشر الالتزام الزمني],14)="متأخر",INDEX(tblDeliverables[المخرج],14),""),"") | R16: =IFERROR(IF(AND(INDEX(tblDeliverables[الأولوية],14)="عالية",INDEX(tblDeliverables[الحالة الحالية],14)<>"معتمد ونافذ",INDEX(tblDeliverables[المخرج],14)<>""),INDEX(tblDeliverables[المخرج],14),""),"") | S16: =IFERROR(IF(INDEX(tblMeetings[الحالة],14)="مفتوح",INDEX(tblMeetings[أهم القرارات],14),""),"") | T16: =IFERROR(IF(AND(INDEX(tblMeetings[تاريخ الاستحقاق],14)<>"",INDEX(tblMeetings[تاريخ الاستحقاق],14)>=TODAY(),INDEX(tblMeetings[تاريخ الاستحقاق],14)<=TODAY()+14,INDEX(tblMeetings[الحالة],14)<>"مغلق"),INDEX(tblMeetings[الإجراءات المطلوبة],14),""),"") | V16: =IF(Q16="",V15,IF(V15="",Q16,V15&"، "&Q16)) -> مصفوفة الصلاحيات الشاملة | W16: =IF(R16="",W15,IF(W15="",R16,W15&"، "&R16)) -> لائحة مجلس الإدارة، لائحة لجنة المراجعة، لائحة لجنة الترشيحات والمكافآت، مصفوفة الصلاحيات الشاملة، سياسة تعارض المصالح، سياسة إدارة المخاطر | X16: =IF(S16="",X15,IF(X15="",S16,X15&"، "&S16)) -> مراجعة حالة المخرجات المتأخرة، الموافقة على رفع لوائح اللجان للمجلس | Y16: =IF(T16="",Y15,IF(Y15="",T16,Y15&"، "&T16)) -> تسريع اعتماد مصفوفة الصلاحيات الشاملة، جدولة جلسة اعتماد لائحة مجلس الإدارة
D17: الحلول القانونية | E17: =COUNTIF(tblDeliverables[المختص / الجهة المراجعة],"الحلول القانونية") -> 0 | Q17: =IFERROR(IF(INDEX(tblDeliverables[مؤشر الالتزام الزمني],15)="متأخر",INDEX(tblDeliverables[المخرج],15),""),"") | R17: =IFERROR(IF(AND(INDEX(tblDeliverables[الأولوية],15)="عالية",INDEX(tblDeliverables[الحالة الحالية],15)<>"معتمد ونافذ",INDEX(tblDeliverables[المخرج],15)<>""),INDEX(tblDeliverables[المخرج],15),""),"") -> سياسة الاستثمار والشركات التابعة | S17: =IFERROR(IF(INDEX(tblMeetings[الحالة],15)="مفتوح",INDEX(tblMeetings[أهم القرارات],15),""),"") | T17: =IFERROR(IF(AND(INDEX(tblMeetings[تاريخ الاستحقاق],15)<>"",INDEX(tblMeetings[تاريخ الاستحقاق],15)>=TODAY(),INDEX(tblMeetings[تاريخ الاستحقاق],15)<=TODAY()+14,INDEX(tblMeetings[الحالة],15)<>"مغلق"),INDEX(tblMeetings[الإجراءات المطلوبة],15),""),"") | V17: =IF(Q17="",V16,IF(V16="",Q17,V16&"، "&Q17)) -> مصفوفة الصلاحيات الشاملة | W17: =IF(R17="",W16,IF(W16="",R17,W16&"، "&R17)) -> لائحة مجلس الإدارة، لائحة لجنة المراجعة، لائحة لجنة الترشيحات والمكافآت، مصفوفة الصلاحيات الشاملة، سياسة تعارض المصالح، سياسة إدارة المخاطر، سياسة الاستثمار والشركات التابعة | X17: =IF(S17="",X16,IF(X16="",S17,X16&"، "&S17)) -> مراجعة حالة المخرجات المتأخرة، الموافقة على رفع لوائح اللجان للمجلس | Y17: =IF(T17="",Y16,IF(Y16="",T17,Y16&"، "&T17)) -> تسريع اعتماد مصفوفة الصلاحيات الشاملة، جدولة جلسة اعتماد لائحة مجلس الإدارة
D18: فريق الحوكمة | E18: =COUNTIF(tblDeliverables[المختص / الجهة المراجعة],"فريق الحوكمة") -> 1 | Q18: =IFERROR(IF(INDEX(tblDeliverables[مؤشر الالتزام الزمني],16)="متأخر",INDEX(tblDeliverables[المخرج],16),""),"") | R18: =IFERROR(IF(AND(INDEX(tblDeliverables[الأولوية],16)="عالية",INDEX(tblDeliverables[الحالة الحالية],16)<>"معتمد ونافذ",INDEX(tblDeliverables[المخرج],16)<>""),INDEX(tblDeliverables[المخرج],16),""),"") | S18: =IFERROR(IF(INDEX(tblMeetings[الحالة],16)="مفتوح",INDEX(tblMeetings[أهم القرارات],16),""),"") | T18: =IFERROR(IF(AND(INDEX(tblMeetings[تاريخ الاستحقاق],16)<>"",INDEX(tblMeetings[تاريخ الاستحقاق],16)>=TODAY(),INDEX(tblMeetings[تاريخ الاستحقاق],16)<=TODAY()+14,INDEX(tblMeetings[الحالة],16)<>"مغلق"),INDEX(tblMeetings[الإجراءات المطلوبة],16),""),"") | V18: =IF(Q18="",V17,IF(V17="",Q18,V17&"، "&Q18)) -> مصفوفة الصلاحيات الشاملة | W18: =IF(R18="",W17,IF(W17="",R18,W17&"، "&R18)) -> لائحة مجلس الإدارة، لائحة لجنة المراجعة، لائحة لجنة الترشيحات والمكافآت، مصفوفة الصلاحيات الشاملة، سياسة تعارض المصالح، سياسة إدارة المخاطر، سياسة الاستثمار والشركات التابعة | X18: =IF(S18="",X17,IF(X17="",S18,X17&"، "&S18)) -> مراجعة حالة المخرجات المتأخرة، الموافقة على رفع لوائح اللجان للمجلس | Y18: =IF(T18="",Y17,IF(Y17="",T18,Y17&"، "&T18)) -> تسريع اعتماد مصفوفة الصلاحيات الشاملة، جدولة جلسة اعتماد لائحة مجلس الإدارة
Q19: =IFERROR(IF(INDEX(tblDeliverables[مؤشر الالتزام الزمني],17)="متأخر",INDEX(tblDeliverables[المخرج],17),""),"") | R19: =IFERROR(IF(AND(INDEX(tblDeliverables[الأولوية],17)="عالية",INDEX(tblDeliverables[الحالة الحالية],17)<>"معتمد ونافذ",INDEX(tblDeliverables[المخرج],17)<>""),INDEX(tblDeliverables[المخرج],17),""),"") -> تطوير الاستراتيجية الشاملة للمجموعة | S19: =IFERROR(IF(INDEX(tblMeetings[الحالة],17)="مفتوح",INDEX(tblMeetings[أهم القرارات],17),""),"") | T19: =IFERROR(IF(AND(INDEX(tblMeetings[تاريخ الاستحقاق],17)<>"",INDEX(tblMeetings[تاريخ الاستحقاق],17)>=TODAY(),INDEX(tblMeetings[تاريخ الاستحقاق],17)<=TODAY()+14,INDEX(tblMeetings[الحالة],17)<>"مغلق"),INDEX(tblMeetings[الإجراءات المطلوبة],17),""),"") | V19: =IF(Q19="",V18,IF(V18="",Q19,V18&"، "&Q19)) -> مصفوفة الصلاحيات الشاملة | W19: =IF(R19="",W18,IF(W18="",R19,W18&"، "&R19)) -> لائحة مجلس الإدارة، لائحة لجنة المراجعة، لائحة لجنة الترشيحات والمكافآت، مصفوفة الصلاحيات الشاملة، سياسة تعارض المصالح، سياسة إدارة المخاطر، سياسة الاستثمار والشركات التابعة، تطوير الاستراتيجية الشاملة للمجموعة | X19: =IF(S19="",X18,IF(X18="",S19,X18&"، "&S19)) -> مراجعة حالة المخرجات المتأخرة، الموافقة على رفع لوائح اللجان للمجلس | Y19: =IF(T19="",Y18,IF(Y18="",T19,Y18&"، "&T19)) -> تسريع اعتماد مصفوفة الصلاحيات الشاملة، جدولة جلسة اعتماد لائحة مجلس الإدارة
Q20: =IFERROR(IF(INDEX(tblDeliverables[مؤشر الالتزام الزمني],18)="متأخر",INDEX(tblDeliverables[المخرج],18),""),"") | R20: =IFERROR(IF(AND(INDEX(tblDeliverables[الأولوية],18)="عالية",INDEX(tblDeliverables[الحالة الحالية],18)<>"معتمد ونافذ",INDEX(tblDeliverables[المخرج],18)<>""),INDEX(tblDeliverables[المخرج],18),""),"") | S20: =IFERROR(IF(INDEX(tblMeetings[الحالة],18)="مفتوح",INDEX(tblMeetings[أهم القرارات],18),""),"") | T20: =IFERROR(IF(AND(INDEX(tblMeetings[تاريخ الاستحقاق],18)<>"",INDEX(tblMeetings[تاريخ الاستحقاق],18)>=TODAY(),INDEX(tblMeetings[تاريخ الاستحقاق],18)<=TODAY()+14,INDEX(tblMeetings[الحالة],18)<>"مغلق"),INDEX(tblMeetings[الإجراءات المطلوبة],18),""),"") | V20: =IF(Q20="",V19,IF(V19="",Q20,V19&"، "&Q20)) -> مصفوفة الصلاحيات الشاملة | W20: =IF(R20="",W19,IF(W19="",R20,W19&"، "&R20)) -> لائحة مجلس الإدارة، لائحة لجنة المراجعة، لائحة لجنة الترشيحات والمكافآت، مصفوفة الصلاحيات الشاملة، سياسة تعارض المصالح، سياسة إدارة المخاطر، سياسة الاستثمار والشركات التابعة، تطوير الاستراتيجية الشاملة للمجموعة | X20: =IF(S20="",X19,IF(X19="",S20,X19&"، "&S20)) -> مراجعة حالة المخرجات المتأخرة، الموافقة على رفع لوائح اللجان للمجلس | Y20: =IF(T20="",Y19,IF(Y19="",T20,Y19&"، "&T20)) -> تسريع اعتماد مصفوفة الصلاحيات الشاملة، جدولة جلسة اعتماد لائحة مجلس الإدارة
Q21: =IFERROR(IF(INDEX(tblDeliverables[مؤشر الالتزام الزمني],19)="متأخر",INDEX(tblDeliverables[المخرج],19),""),"") | R21: =IFERROR(IF(AND(INDEX(tblDeliverables[الأولوية],19)="عالية",INDEX(tblDeliverables[الحالة الحالية],19)<>"معتمد ونافذ",INDEX(tblDeliverables[المخرج],19)<>""),INDEX(tblDeliverables[المخرج],19),""),"") | S21: =IFERROR(IF(INDEX(tblMeetings[الحالة],19)="مفتوح",INDEX(tblMeetings[أهم القرارات],19),""),"") | T21: =IFERROR(IF(AND(INDEX(tblMeetings[تاريخ الاستحقاق],19)<>"",INDEX(tblMeetings[تاريخ الاستحقاق],19)>=TODAY(),INDEX(tblMeetings[تاريخ الاستحقاق],19)<=TODAY()+14,INDEX(tblMeetings[الحالة],19)<>"مغلق"),INDEX(tblMeetings[الإجراءات المطلوبة],19),""),"") | V21: =IF(Q21="",V20,IF(V20="",Q21,V20&"، "&Q21)) -> مصفوفة الصلاحيات الشاملة | W21: =IF(R21="",W20,IF(W20="",R21,W20&"، "&R21)) -> لائحة مجلس الإدارة، لائحة لجنة المراجعة، لائحة لجنة الترشيحات والمكافآت، مصفوفة الصلاحيات الشاملة، سياسة تعارض المصالح، سياسة إدارة المخاطر، سياسة الاستثمار والشركات التابعة، تطوير الاستراتيجية الشاملة للمجموعة | X21: =IF(S21="",X20,IF(X20="",S21,X20&"، "&S21)) -> مراجعة حالة المخرجات المتأخرة، الموافقة على رفع لوائح اللجان للمجلس | Y21: =IF(T21="",Y20,IF(Y20="",T21,Y20&"، "&T21)) -> تسريع اعتماد مصفوفة الصلاحيات الشاملة، جدولة جلسة اعتماد لائحة مجلس الإدارة
Q22: =IFERROR(IF(INDEX(tblDeliverables[مؤشر الالتزام الزمني],20)="متأخر",INDEX(tblDeliverables[المخرج],20),""),"") | R22: =IFERROR(IF(AND(INDEX(tblDeliverables[الأولوية],20)="عالية",INDEX(tblDeliverables[الحالة الحالية],20)<>"معتمد ونافذ",INDEX(tblDeliverables[المخرج],20)<>""),INDEX(tblDeliverables[المخرج],20),""),"") | S22: =IFERROR(IF(INDEX(tblMeetings[الحالة],20)="مفتوح",INDEX(tblMeetings[أهم القرارات],20),""),"") | T22: =IFERROR(IF(AND(INDEX(tblMeetings[تاريخ الاستحقاق],20)<>"",INDEX(tblMeetings[تاريخ الاستحقاق],20)>=TODAY(),INDEX(tblMeetings[تاريخ الاستحقاق],20)<=TODAY()+14,INDEX(tblMeetings[الحالة],20)<>"مغلق"),INDEX(tblMeetings[الإجراءات المطلوبة],20),""),"") | V22: =IF(Q22="",V21,IF(V21="",Q22,V21&"، "&Q22)) -> مصفوفة الصلاحيات الشاملة | W22: =IF(R22="",W21,IF(W21="",R22,W21&"، "&R22)) -> لائحة مجلس الإدارة، لائحة لجنة المراجعة، لائحة لجنة الترشيحات والمكافآت، مصفوفة الصلاحيات الشاملة، سياسة تعارض المصالح، سياسة إدارة المخاطر، سياسة الاستثمار والشركات التابعة، تطوير الاستراتيجية الشاملة للمجموعة | X22: =IF(S22="",X21,IF(X21="",S22,X21&"، "&S22)) -> مراجعة حالة المخرجات المتأخرة، الموافقة على رفع لوائح اللجان للمجلس | Y22: =IF(T22="",Y21,IF(Y21="",T22,Y21&"، "&T22)) -> تسريع اعتماد مصفوفة الصلاحيات الشاملة، جدولة جلسة اعتماد لائحة مجلس الإدارة
Q23: =IFERROR(IF(INDEX(tblDeliverables[مؤشر الالتزام الزمني],21)="متأخر",INDEX(tblDeliverables[المخرج],21),""),"") | R23: =IFERROR(IF(AND(INDEX(tblDeliverables[الأولوية],21)="عالية",INDEX(tblDeliverables[الحالة الحالية],21)<>"معتمد ونافذ",INDEX(tblDeliverables[المخرج],21)<>""),INDEX(tblDeliverables[المخرج],21),""),"") | S23: =IFERROR(IF(INDEX(tblMeetings[الحالة],21)="مفتوح",INDEX(tblMeetings[أهم القرارات],21),""),"") | T23: =IFERROR(IF(AND(INDEX(tblMeetings[تاريخ الاستحقاق],21)<>"",INDEX(tblMeetings[تاريخ الاستحقاق],21)>=TODAY(),INDEX(tblMeetings[تاريخ الاستحقاق],21)<=TODAY()+14,INDEX(tblMeetings[الحالة],21)<>"مغلق"),INDEX(tblMeetings[الإجراءات المطلوبة],21),""),"") | V23: =IF(Q23="",V22,IF(V22="",Q23,V22&"، "&Q23)) -> مصفوفة الصلاحيات الشاملة | W23: =IF(R23="",W22,IF(W22="",R23,W22&"، "&R23)) -> لائحة مجلس الإدارة، لائحة لجنة المراجعة، لائحة لجنة الترشيحات والمكافآت، مصفوفة الصلاحيات الشاملة، سياسة تعارض المصالح، سياسة إدارة المخاطر، سياسة الاستثمار والشركات التابعة، تطوير الاستراتيجية الشاملة للمجموعة | X23: =IF(S23="",X22,IF(X22="",S23,X22&"، "&S23)) -> مراجعة حالة المخرجات المتأخرة، الموافقة على رفع لوائح اللجان للمجلس | Y23: =IF(T23="",Y22,IF(Y22="",T23,Y22&"، "&T23)) -> تسريع اعتماد مصفوفة الصلاحيات الشاملة، جدولة جلسة اعتماد لائحة مجلس الإدارة
Q24: =IFERROR(IF(INDEX(tblDeliverables[مؤشر الالتزام الزمني],22)="متأخر",INDEX(tblDeliverables[المخرج],22),""),"") | R24: =IFERROR(IF(AND(INDEX(tblDeliverables[الأولوية],22)="عالية",INDEX(tblDeliverables[الحالة الحالية],22)<>"معتمد ونافذ",INDEX(tblDeliverables[المخرج],22)<>""),INDEX(tblDeliverables[المخرج],22),""),"") -> مؤشرات الأداء الاستراتيجية | S24: =IFERROR(IF(INDEX(tblMeetings[الحالة],22)="مفتوح",INDEX(tblMeetings[أهم القرارات],22),""),"") | T24: =IFERROR(IF(AND(INDEX(tblMeetings[تاريخ الاستحقاق],22)<>"",INDEX(tblMeetings[تاريخ الاستحقاق],22)>=TODAY(),INDEX(tblMeetings[تاريخ الاستحقاق],22)<=TODAY()+14,INDEX(tblMeetings[الحالة],22)<>"مغلق"),INDEX(tblMeetings[الإجراءات المطلوبة],22),""),"") | V24: =IF(Q24="",V23,IF(V23="",Q24,V23&"، "&Q24)) -> مصفوفة الصلاحيات الشاملة | W24: =IF(R24="",W23,IF(W23="",R24,W23&"، "&R24)) -> لائحة مجلس الإدارة، لائحة لجنة المراجعة، لائحة لجنة الترشيحات والمكافآت، مصفوفة الصلاحيات الشاملة، سياسة تعارض المصالح، سياسة إدارة المخاطر، سياسة الاستثمار والشركات التابعة، تطوير الاستراتيجية الشاملة للمجموعة، مؤشرات الأداء الاستراتيجية | X24: =IF(S24="",X23,IF(X23="",S24,X23&"، "&S24)) -> مراجعة حالة المخرجات المتأخرة، الموافقة على رفع لوائح اللجان للمجلس | Y24: =IF(T24="",Y23,IF(Y23="",T24,Y23&"، "&T24)) -> تسريع اعتماد مصفوفة الصلاحيات الشاملة، جدولة جلسة اعتماد لائحة مجلس الإدارة
Q25: =IFERROR(IF(INDEX(tblDeliverables[مؤشر الالتزام الزمني],23)="متأخر",INDEX(tblDeliverables[المخرج],23),""),"") | R25: =IFERROR(IF(AND(INDEX(tblDeliverables[الأولوية],23)="عالية",INDEX(tblDeliverables[الحالة الحالية],23)<>"معتمد ونافذ",INDEX(tblDeliverables[المخرج],23)<>""),INDEX(tblDeliverables[المخرج],23),""),"") | S25: =IFERROR(IF(INDEX(tblMeetings[الحالة],23)="مفتوح",INDEX(tblMeetings[أهم القرارات],23),""),"") | T25: =IFERROR(IF(AND(INDEX(tblMeetings[تاريخ الاستحقاق],23)<>"",INDEX(tblMeetings[تاريخ الاستحقاق],23)>=TODAY(),INDEX(tblMeetings[تاريخ الاستحقاق],23)<=TODAY()+14,INDEX(tblMeetings[الحالة],23)<>"مغلق"),INDEX(tblMeetings[الإجراءات المطلوبة],23),""),"") | V25: =IF(Q25="",V24,IF(V24="",Q25,V24&"، "&Q25)) -> مصفوفة الصلاحيات الشاملة | W25: =IF(R25="",W24,IF(W24="",R25,W24&"، "&R25)) -> لائحة مجلس الإدارة، لائحة لجنة المراجعة، لائحة لجنة الترشيحات والمكافآت، مصفوفة الصلاحيات الشاملة، سياسة تعارض المصالح، سياسة إدارة المخاطر، سياسة الاستثمار والشركات التابعة، تطوير الاستراتيجية الشاملة للمجموعة، مؤشرات الأداء الاستراتيجية | X25: =IF(S25="",X24,IF(X24="",S25,X24&"، "&S25)) -> مراجعة حالة المخرجات المتأخرة، الموافقة على رفع لوائح اللجان للمجلس | Y25: =IF(T25="",Y24,IF(Y24="",T25,Y24&"، "&T25)) -> تسريع اعتماد مصفوفة الصلاحيات الشاملة، جدولة جلسة اعتماد لائحة مجلس الإدارة
Q26: =IFERROR(IF(INDEX(tblDeliverables[مؤشر الالتزام الزمني],24)="متأخر",INDEX(tblDeliverables[المخرج],24),""),"") | R26: =IFERROR(IF(AND(INDEX(tblDeliverables[الأولوية],24)="عالية",INDEX(tblDeliverables[الحالة الحالية],24)<>"معتمد ونافذ",INDEX(tblDeliverables[المخرج],24)<>""),INDEX(tblDeliverables[المخرج],24),""),"") | S26: =IFERROR(IF(INDEX(tblMeetings[الحالة],24)="مفتوح",INDEX(tblMeetings[أهم القرارات],24),""),"") | T26: =IFERROR(IF(AND(INDEX(tblMeetings[تاريخ الاستحقاق],24)<>"",INDEX(tblMeetings[تاريخ الاستحقاق],24)>=TODAY(),INDEX(tblMeetings[تاريخ الاستحقاق],24)<=TODAY()+14,INDEX(tblMeetings[الحالة],24)<>"مغلق"),INDEX(tblMeetings[الإجراءات المطلوبة],24),""),"") | V26: =IF(Q26="",V25,IF(V25="",Q26,V25&"، "&Q26)) -> مصفوفة الصلاحيات الشاملة | W26: =IF(R26="",W25,IF(W25="",R26,W25&"، "&R26)) -> لائحة مجلس الإدارة، لائحة لجنة المراجعة، لائحة لجنة الترشيحات والمكافآت، مصفوفة الصلاحيات الشاملة، سياسة تعارض المصالح، سياسة إدارة المخاطر، سياسة الاستثمار والشركات التابعة، تطوير الاستراتيجية الشاملة للمجموعة، مؤشرات الأداء الاستراتيجية | X26: =IF(S26="",X25,IF(X25="",S26,X25&"، "&S26)) -> مراجعة حالة المخرجات المتأخرة، الموافقة على رفع لوائح اللجان للمجلس | Y26: =IF(T26="",Y25,IF(Y25="",T26,Y25&"، "&T26)) -> تسريع اعتماد مصفوفة الصلاحيات الشاملة، جدولة جلسة اعتماد لائحة مجلس الإدارة
Q27: =IFERROR(IF(INDEX(tblDeliverables[مؤشر الالتزام الزمني],25)="متأخر",INDEX(tblDeliverables[المخرج],25),""),"") | R27: =IFERROR(IF(AND(INDEX(tblDeliverables[الأولوية],25)="عالية",INDEX(tblDeliverables[الحالة الحالية],25)<>"معتمد ونافذ",INDEX(tblDeliverables[المخرج],25)<>""),INDEX(tblDeliverables[المخرج],25),""),"") | S27: =IFERROR(IF(INDEX(tblMeetings[الحالة],25)="مفتوح",INDEX(tblMeetings[أهم القرارات],25),""),"") | T27: =IFERROR(IF(AND(INDEX(tblMeetings[تاريخ الاستحقاق],25)<>"",INDEX(tblMeetings[تاريخ الاستحقاق],25)>=TODAY(),INDEX(tblMeetings[تاريخ الاستحقاق],25)<=TODAY()+14,INDEX(tblMeetings[الحالة],25)<>"مغلق"),INDEX(tblMeetings[الإجراءات المطلوبة],25),""),"") | V27: =IF(Q27="",V26,IF(V26="",Q27,V26&"، "&Q27)) -> مصفوفة الصلاحيات الشاملة | W27: =IF(R27="",W26,IF(W26="",R27,W26&"، "&R27)) -> لائحة مجلس الإدارة، لائحة لجنة المراجعة، لائحة لجنة الترشيحات والمكافآت، مصفوفة الصلاحيات الشاملة، سياسة تعارض المصالح، سياسة إدارة المخاطر، سياسة الاستثمار والشركات التابعة، تطوير الاستراتيجية الشاملة للمجموعة، مؤشرات الأداء الاستراتيجية | X27: =IF(S27="",X26,IF(X26="",S27,X26&"، "&S27)) -> مراجعة حالة المخرجات المتأخرة، الموافقة على رفع لوائح اللجان للمجلس | Y27: =IF(T27="",Y26,IF(Y26="",T27,Y26&"، "&T27)) -> تسريع اعتماد مصفوفة الصلاحيات الشاملة، جدولة جلسة اعتماد لائحة مجلس الإدارة
Q28: =IFERROR(IF(INDEX(tblDeliverables[مؤشر الالتزام الزمني],26)="متأخر",INDEX(tblDeliverables[المخرج],26),""),"") | R28: =IFERROR(IF(AND(INDEX(tblDeliverables[الأولوية],26)="عالية",INDEX(tblDeliverables[الحالة الحالية],26)<>"معتمد ونافذ",INDEX(tblDeliverables[المخرج],26)<>""),INDEX(tblDeliverables[المخرج],26),""),"") | S28: =IFERROR(IF(INDEX(tblMeetings[الحالة],26)="مفتوح",INDEX(tblMeetings[أهم القرارات],26),""),"") | T28: =IFERROR(IF(AND(INDEX(tblMeetings[تاريخ الاستحقاق],26)<>"",INDEX(tblMeetings[تاريخ الاستحقاق],26)>=TODAY(),INDEX(tblMeetings[تاريخ الاستحقاق],26)<=TODAY()+14,INDEX(tblMeetings[الحالة],26)<>"مغلق"),INDEX(tblMeetings[الإجراءات المطلوبة],26),""),"") | V28: =IF(Q28="",V27,IF(V27="",Q28,V27&"، "&Q28)) -> مصفوفة الصلاحيات الشاملة | W28: =IF(R28="",W27,IF(W27="",R28,W27&"، "&R28)) -> لائحة مجلس الإدارة، لائحة لجنة المراجعة، لائحة لجنة الترشيحات والمكافآت، مصفوفة الصلاحيات الشاملة، سياسة تعارض المصالح، سياسة إدارة المخاطر، سياسة الاستثمار والشركات التابعة، تطوير الاستراتيجية الشاملة للمجموعة، مؤشرات الأداء الاستراتيجية | X28: =IF(S28="",X27,IF(X27="",S28,X27&"، "&S28)) -> مراجعة حالة المخرجات المتأخرة، الموافقة على رفع لوائح اللجان للمجلس | Y28: =IF(T28="",Y27,IF(Y27="",T28,Y27&"، "&T28)) -> تسريع اعتماد مصفوفة الصلاحيات الشاملة، جدولة جلسة اعتماد لائحة مجلس الإدارة
